Workbook
Name Acceptable_findings_MJ: VLOOKUP('Sampling Plan Inspection'!$D$7,'AQL Table'!$C$27:$O$44,HLOOKUP('Sampling Plan Inspection'!$J$7,'AQL Table'!$E$24:$O$26,3),FALSE)
Name Acceptable_findings_Mn: VLOOKUP('Sampling Plan Inspection'!$D$7,'AQL Table'!$C$27:$O$42,HLOOKUP('Sampling Plan Inspection'!$H$7,'AQL Table'!$E$24:$O$26,3))
Name Actual_Minor_Acceptable_Findings: VLOOKUP('Sampling Plan Inspection'!$F$7,'AQL Table'!$D$27:$O$42,HLOOKUP('Sampling Plan Inspection'!$H$7,'AQL Table'!$E$24:$O$26,3)-1)

Sheet Sampling Plan Inspection
A1: Workload estimate
F2: = Input the blank cells
F3: = Calculated cells
B5: Sampling size | H5: Acceptable Quality Level | N5: Final Sampling size check
B6: Total Production size | C6: Inspection level | D6: Sampling size Letter | E6: Initial Sampling Size | F6: Sampling Size | H6: Minor AQL | I6: Minor Acceptable findings | J6: Major AQL | K6: Minor Acceptable findings | L6: Major Acceptable findings | N6: Initial sample size validation
B7: 20000 | C7: II | D7: =VLOOKUP(1,'AQL Table'!B5:K19,HLOOKUP('Sampling Plan Inspection'!C7,'AQL Table'!E3:K6,2)) -> M | E7: =VLOOKUP(D7,'AQL Table'!C29:D44,2) -> 315 | F7: =IF(Acceptable_findings_MJ="+",HLOOKUP(J7,'AQL Table'!C24:P27,4),IF(Acceptable_findings_MJ="++",HLOOKUP(J7,'AQL Table'!C24:P28,5),E7)) -> 315 | H7: 4 | I7: =IF(Acceptable_findings_Mn="+",0,IF(Acceptable_findings_Mn="++",1,Acceptable_findings_Mn)) -> 21 | J7: 2.5 | K7: =IF(Actual_Minor_Acceptable_Findings="+",0,IF(Actual_Minor_Acceptable_Findings="++",1,Actual_Minor_Acceptable_Findings)) -> 21 | L7: =IF(Acceptable_findings_MJ="+",0,IF(Acceptable_findings_MJ="++",1,Acceptable_findings_MJ)) -> 14 | N7: =IF(ISNUMBER(Acceptable_findings_MJ)=TRUE,"OK","NOK") -> OK
B10: Product information | H10: Workload calculation estimate
B11: Product category | F11: Number of item for this day | H11: Max # item per day | K11: Max quantity of item per day | L11: Manday needed
B12: Simple hardgoods | F12: 2 | H12: =VLOOKUP(B12,'AQL Table'!C47:O59,11,FALSE) -> 5 | K12: =VLOOKUP(B12,'AQL Table'!C47:O59,13,FALSE) -> 315 | L12: =ROUNDUP(MAX(F7/K12,F12/H12),0) -> 1
B13: =VLOOKUP(B12,'AQL Table'!C47:O59,5,FALSE) -> For example: Metal product: kitchenware, cookware, knife Stationery: pen, pencil, paper or book with pages less than 100 Porcelain product: kitchenware, teapot, cup
B27: Remarks:
C28: The above calculation is an estimate, for special case kindly contact CNS planning team for confirmation
C29: This calculation is made in order to ensure the customer requirement is satisfied
C30: Sampling plan is calculated according to ISO 2859 (commonly used for inspection)
L31: www.cn-Q.com

Sheet AQL Table
E1: SAMPLING SIZE CODE LETTERS
C2: Lot Size | E2: General Inspection Level | H2: Special Inspection Level
C3: to | E3: I | F3: II | G3: III | H3: S1 | I3: S2 | J3: S3 | K3: S4
B4: 1 | C4: 2 | D4: 3 | E4: 4 | F4: 5 | G4: 6 | H4: 7 | I4: 8 | J4: 9 | K4: 10
A5: =C5-'Sampling Plan Inspection'!$B$7 -> -19998 | B5: =IF(A6>0,1+B3,0) -> 0 | C5: 2 | D5: 8 | E5: A | F5: A | G5: B | H5: A | I5: A | J5: A | K5: A
A6: =C6-'Sampling Plan Inspection'!$B$7 -> -19991 | B6: =IF(A7>0,1+B5,0) -> 0 | C6: 9 | D6: 15 | E6: A | F6: B | G6: C | H6: A | I6: A | J6: A | K6: A
A7: =C7-'Sampling Plan Inspection'!$B$7 -> -19984 | B7: =IF(A8>0,1+B6,0) -> 0 | C7: 16 | D7: 25 | E7: B | F7: C | G7: D | H7: A | I7: A | J7: B | K7: B
A8: =C8-'Sampling Plan Inspection'!$B$7 -> -19974 | B8: =IF(A9>0,1+B7,0) -> 0 | C8: 26 | D8: 50 | E8: C | F8: D | G8: E | H8: A | I8: B | J8: B | K8: C
A9: =C9-'Sampling Plan Inspection'!$B$7 -> -19949 | B9: =IF(A10>0,1+B8,0) -> 0 | C9: 51 | D9: 90 | E9: C | F9: E | G9: F | H9: B | I9: B | J9: C | K9: C
A10: =C10-'Sampling Plan Inspection'!$B$7 -> -19909 | B10: =IF(A11>0,1+B9,0) -> 0 | C10: 91 | D10: 150 | E10: D | F10: F | G10: G | H10: B | I10: B | J10: C | K10: D
A11: =C11-'Sampling Plan Inspection'!$B$7 -> -19849 | B11: =IF(A12>0,1+B10,0) -> 0 | C11: 151 | D11: 280 | E11: E | F11: G | G11: H | H11: B | I11: C | J11: D | K11: E
A12: =C12-'Sampling Plan Inspection'!$B$7 -> -19719 | B12: =IF(A13>0,1+B11,0) -> 0 | C12: 281 | D12: 500 | E12: F | F12: H | G12: J | H12: B | I12: C | J12: D | K12: E
A13: =C13-'Sampling Plan Inspection'!$B$7 -> -19499 | B13: =IF(A14>0,1+B12,0) -> 0 | C13: 501 | D13: 1200 | E13: G | F13: J | G13: K | H13: C | I13: C | J13: E | K13: F
A14: =C14-'Sampling Plan Inspection'!$B$7 -> -18799 | B14: =IF(A15>0,1+B13,0) -> 0 | C14: 1201 | D14: 3200 | E14: H | F14: K | G14: L | H14: C | I14: D | J14: E | K14: G
A15: =C15-'Sampling Plan Inspection'!$B$7 -> -16799 | B15: =IF(A16>0,1+B14,0) -> 0 | C15: 3201 | D15: 10000 | E15: J | F15: L | G15: M | H15: C | I15: D | J15: F | K15: G
A16: =C16-'Sampling Plan Inspection'!$B$7 -> -9999 | B16: =IF(A17>0,1+B15,0) -> 1 | C16: 10001 | D16: 35000 | E16: K | F16: M | G16: N | H16: C | I16: D | J16: F | K16: H
A17: =C17-'Sampling Plan Inspection'!$B$7 -> 15001 | B17: =IF(A18>0,1+B16,0) -> 2 | C17: 35001 | D17: 150000 | E17: L | F17: N | G17: P | H17: D | I17: E | J17: G | K17: J
... A19: =C19-'Sampling Plan Inspection'!$B$7 -> 480001 | B19: =IF(A20>0,1+B18,0) -> 4 | C19: 500001 | D19: 1000000000 | E19: N | F19: Q | G19: R | H19: D | I19: E | J19: H | K19: K
A20: =D19-'Sampling Plan Inspection'!$B$7 -> 999980000
E22: SINGLE SAMPLING PLANS FOR NORMAL INSPECTION
C23: Sample Size Code Letter | D23: Sample Size | E23: Acceptable Quality Level (Normal Inspection)
E24: 0.065 | F24: 0.1 | G24: 0.15 | H24: 0.25 | I24: 0.4 | J24: 0.65 | K24: 1 | L24: 1.5 | M24: 2.5 | N24: 4 | O24: 6.5
E25: Acceptable findings | F25: Acceptable findings | G25: Acceptable findings | H25: Acceptable findings | I25: Acceptable findings | J25: Acceptable findings | K25: Acceptable findings | L25: Acceptable findings | M25: Acceptable findings | N25: Acceptable findings | O25: Acceptable findings
C26: 1 | D26: 2 | E26: 3 | F26: 4 | G26: 5 | H26: 6 | I26: 7 | J26: 8 | K26: 9 | L26: 10 | M26: 11 | N26: 12 | O26: 13
C27: Minimum sampling size | E27: 200 | F27: 125 | G27: 80 | H27: 50 | I27: 32 | J27: 20 | K27: 13 | L27: 8 | M27: 5 | N27: 3 | O27: 2
C28: Intermediate sampling size | E28: 800 | F28: 500 | G28: 315 | H28: 200 | I28: 125 | J28: 80 | K28: 50 | L28: 32 | M28: 20 | N28: 13 | O28: 8
B29: 1 | C29: A | D29: 2 | E29: + | F29: + | G29: + | H29: + | I29: + | J29: + | K29: + | L29: + | M29: + | N29: + | O29: 0
B30: 2 | C30: B | D30: 3 | E30: + | F30: + | G30: + | H30: + | I30: + | J30: + | K30: + | L30: + | M30: + | N30: 0 | O30: 0
B31: 3 | C31: C | D31: 5 | E31: + | F31: + | G31: + | H31: + | I31: + | J31: + | K31: + | L31: + | M31: 0 | N31: 0 | O31: ++
B32: 4 | C32: D | D32: 8 | E32: + | F32: + | G32: + | H32: + | I32: + | J32: + | K32: + | L32: 0 | M32: 0 | N32: ++ | O32: 1
B33: 5 | C33: E | D33: 13 | E33: + | F33: + | G33: + | H33: + | I33: + | J33: + | K33: 0 | L33: 0 | M33: ++ | N33: 1 | O33: 2
B34: 6 | C34: F | D34: 20 | E34: + | F34: + | G34: + | H34: + | I34: + | J34: 0 | K34: 0 | L34: ++ | M34: 1 | N34: 2 | O34: 3
B35: 7 | C35: G | D35: 32 | E35: + | F35: + | G35: + | H35: + | I35: 0 | J35: 0 | K35: ++ | L35: 1 | M35: 2 | N35: 3 | O35: 5
B36: 8 | C36: H | D36: 50 | E36: + | F36: + | G36: + | H36: 0 | I36: 0 | J36: ++ | K36: 1 | L36: 2 | M36: 3 | N36: 5 | O36: 7
B37: 9 | C37: J | D37: 80 | E37: + | F37: + | G37: 0 | H37: 0 | I37: ++ | J37: 1 | K37: 2 | L37: 3 | M37: 5 | N37: 7 | O37: 10
B38: 10 | C38: K | D38: 125 | E38: + | F38: 0 | G38: 0 | H38: ++ | I38: 1 | J38: 2 | K38: 3 | L38: 5 | M38: 7 | N38: 10 | O38: 14
B39: 11 | C39: L | D39: 200 | E39: 0 | F39: 0 | G39: ++ | H39: 1 | I39: 2 | J39: 3 | K39: 5 | L39: 7 | M39: 10 | N39: 14 | O39: 21
B40: 12 | C40: M | D40: 315 | E40: 0 | F40: ++ | G40: 1 | H40: 2 | I40: 3 | J40: 5 | K40: 7 | L40: 10 | M40: 14 | N40: 21 | O40: 21
B41: 13 | C41: N | D41: 500 | E41: ++ | F41: 1 | G41: 2 | H41: 3 | I41: 5 | J41: 7 | K41: 10 | L41: 14 | M41: 21 | N41: 21 | O41: 21
B42: 14 | C42: P | D42: 800 | E42: 1 | F42: 2 | G42: 3 | H42: 5 | I42: 7 | J42: 10 | K42: 14 | L42: 21 | M42: 21 | N42: 21 | O42: 21
...

Sheet details
A1: Product category | E1: Description | K1: Max # item per day | M1: Max quantity of item per day
A2: General hardgoods without electric function | E2: For example: Metal product: kitchenware, cookware, knife Stationery: pen, pencil, paper or book with pages less than 100 Toys: soft, stuffing, plastic, wooden, metal Porcelain product: kitchenware, teapot, cup | K2: 4 | M2: 315
A3: Simple Softlines | E3: For example: Pillow, towel, socks, backpack, bag, umbrella, fabric item | K3: 4 | M3: 200
A4: Simple electric product or other hardgoods | E4: For example: Stationery Luggage Furniture: table, chair, outdoor or indoor furniture Simple electric product: watch, clock, scale, USB | K4: 4 | M4: 125
A5: Softlines | E5: For example: Shirt, blouse, outerwear, jacket, sweater, jeans, underwear, t-shirt, trousers, shorts, skirt, Jacket, bra, quilt, shoes, luggage | K5: 3 | M5: 125
A6: Electrical appliance | E6: For example: Toys: electric toy with wheel or assembly toy, adapter toy Electric appliance: heater, radiator, lighting, juicer, toaster, kettle, pot, coffee machine, radio, loudspeaker, fridge | K6: 3 | M6: 80
A7: Complex electrical appliance | E7: For example: DVD system sets with speaker, VCD system sets with speaker, TV sets, Computer game sets, Spa, Sauna cabine | K7: 3 | M7: 50

Sheet Workload picking
B6: Max number of picking per day | F6: 8 | G6: items
B8: Additionnal +50USD per 1 more items
